Traceback (most recent call last):
  File "C:\Users\trabi\anaconda3\lib\site-packages\jupyter_cache\executors\utils.py", line 58, in single_nb_execution
    executenb(
  File "C:\Users\trabi\anaconda3\lib\site-packages\nbclient\client.py", line 1204, in execute
    return NotebookClient(nb=nb, resources=resources, km=km, **kwargs).execute()
  File "C:\Users\trabi\anaconda3\lib\site-packages\nbclient\util.py", line 84, in wrapped
    return just_run(coro(*args, **kwargs))
  File "C:\Users\trabi\anaconda3\lib\site-packages\nbclient\util.py", line 62, in just_run
    return loop.run_until_complete(coro)
  File "C:\Users\trabi\anaconda3\lib\asyncio\base_events.py", line 649, in run_until_complete
    return future.result()
  File "C:\Users\trabi\anaconda3\lib\site-packages\nbclient\client.py", line 663, in async_execute
    await self.async_execute_cell(
  File "C:\Users\trabi\anaconda3\lib\site-packages\nbclient\client.py", line 965, in async_execute_cell
    await self._check_raise_for_error(cell, cell_index, exec_reply)
  File "C:\Users\trabi\anaconda3\lib\site-packages\nbclient\client.py", line 862, in _check_raise_for_error
    raise CellExecutionError.from_cell_and_msg(cell, exec_reply_content)
nbclient.exceptions.CellExecutionError: An error occurred while executing the following cell:
------------------
sns.lmplot("PCA1", "PCA2", hue='label', data=df, fit_reg=False);
------------------

[1;31m---------------------------------------------------------------------------[0m
[1;31mTypeError[0m                                 Traceback (most recent call last)
Cell [1;32mIn[59], line 1[0m
[1;32m----> 1[0m [43msns[49m[38;5;241;43m.[39;49m[43mlmplot[49m[43m([49m[38;5;124;43m"[39;49m[38;5;124;43mPCA1[39;49m[38;5;124;43m"[39;49m[43m,[49m[43m [49m[38;5;124;43m"[39;49m[38;5;124;43mPCA2[39;49m[38;5;124;43m"[39;49m[43m,[49m[43m [49m[43mhue[49m[38;5;241;43m=[39;49m[38;5;124;43m'[39;49m[38;5;124;43mlabel[39;49m[38;5;124;43m'[39;49m[43m,[49m[43m [49m[43mdata[49m[38;5;241;43m=[39;49m[43mdf[49m[43m,[49m[43m [49m[43mfit_reg[49m[38;5;241;43m=[39;49m[38;5;28;43;01mFalse[39;49;00m[43m)[49m

[1;31mTypeError[0m: lmplot() got multiple values for argument 'data'
TypeError: lmplot() got multiple values for argument 'data'

